Workbook

Sheet Assumptions
A1: PROJECT ASSUMPTIONS — Company A Sugar Processing Plant
A2: All monetary values in IDR
A4: PROJECT TIMELINE
A5: Construction period (years) | B5: 2
A6: Project tenure (years) | B6: 30
A7: Total project life (years) | B7: =B5+B6 -> 32
A9: INVESTMENT
A10: Total investment (IDR) | B10: 1250000000000
A11: Investment per construction yr | B11: =B10/B5 -> 625000000000
A12: Capex cycle (every N years) | B12: 5
A13: Maintenance capex (% of invest) | B13: =1% -> 0.01
A14: Maintenance capex (IDR) | B14: =B10*B13 -> 12500000000
A16: DEPRECIATION
A17: Depreciation method | B17: Straight-line
A18: Economic life = project tenure | B18: =B6&" years" -> 30 years
A19: Annual depreciation | B19: =B10/B6 -> 4.1666667e+10
A21: SALARY (construction period)
A22: Salary Yr 1 construction | B22: 10000000000
A23: Annual inflation rate | B23: 0.035
A24: Salary Yr 2 construction | B24: =B22*(1+B23) -> 10350000000
A26: REVENUE & GROWTH
A27: Sales Yr 1 (full operation) | B27: 550000000000
A28: Sugar price per tonne (Yr 1) | B28: 10000000
A29: Sales volume Yr 1 (tonnes) | B29: =B27/B28 -> 55000
A30: Sales growth over inflation | B30: 0.07
A31: Effective sales growth rate | B31: =B23+B30 -> 0.105
A33: COST STRUCTURE
A34: EBITDA margin | B34: 0.4
A35: Fixed cost Yr 1 (full oper.) | B35: 115000000000
A36: Fixed cost grows with inflation | B36: Yes
A38: OPPORTUNITY COST
A39: Forgone net cash flow/yr | B39: 50000000000
A41: TAX
A42: Corporate tax rate | B42: 0.25
A43: Tax during construction | B43: Waived
A45: FINANCING
A46: Debt proportion | B46: 0.65
A47: Equity proportion | B47: =1-B46 -> 0.35
A48: Bond coupon rate | B48: 0.115
A49: Bond issued at par | B49: Yes
...

Sheet WACC
A1: WACC CALCULATION — Miller-Modigliani Theorem
A3: INPUTS (from Assumptions)
A4: Debt proportion (Wd) | B4: =Assumptions!B46 -> 0.65
A5: Equity proportion (We) | B5: =Assumptions!B47 -> 0.35
A6: Cost of debt (Kd) = coupon | B6: =Assumptions!B48 -> 0.115
A7: Tax rate | B7: =Assumptions!B42 -> 0.25
A8: Unlevered cost of equity Ku | B8: =Assumptions!B51 -> 0.13
A10: MILLER-MODIGLIANI (with tax shield)
A11: D/E ratio | B11: =B4/B5 -> 1.8571429
A12: Levered Ke (MM Prop II):
A13: Ke = Ku + (Ku-Kd)×(D/E)×(1-T) | B13: =B8+(B8-B6)*B11*(1-B7) -> 0.15089286
A15: WACC CALCULATION
A16: WACC = Wd×Kd×(1-T) + We×Ke | B16: =B4*B6*(1-B7)+B5*B13 -> 0.108875
A17: Required rate of return (WACC+1%) | B17: =B16+1% -> 0.118875
A19: SUMMARY
A20: Unlevered Ku | B20: =B8 -> 0.13
A21: Levered Ke | B21: =B13 -> 0.15089286
A22: Cost of debt Kd | B22: =B6 -> 0.115
A23: After-tax Kd | B23: =B6*(1-B7) -> 0.08625
A24: WACC | B24: =B16 -> 0.108875
A25: Discount rate | B25: =B17 -> 0.118875

Sheet Income & Cash Flow
A1: PROJECTED INCOME STATEMENT & CASH FLOW (IDR)
B2: Construction | D2: Operation Period (Year 1 – 30)
B3: Const. Yr 1 | C3: Const. Yr 2 | D3: Op. Yr 1 | E3: Op. Yr 2 | F3: Op. Yr 3 | G3: Op. Yr 4 | H3: Op. Yr 5 | I3: Op. Yr 6 | J3: Op. Yr 7 | K3: Op. Yr 8 | L3: Op. Yr 9 | M3: Op. Yr 10 | N3: Op. Yr 11 | O3: Op. Yr 12 | P3: Op. Yr 13 | Q3: Op. Yr 14 | R3: Op. Yr 15 | S3: Op. Yr 16 | T3: Op. Yr 17 | U3: Op. Yr 18 | V3: Op. Yr 19 | W3: Op. Yr 20 | X3: Op. Yr 21 | Y3: Op. Yr 22 | Z3: Op. Yr 23 | AA3: Op. Yr 24 | AB3: Op. Yr 25 | AC3: Op. Yr 26 | AD3: Op. Yr 27 | AE3: Op. Yr 28 | AF3: Op. Yr 29 | AG3: Op. Yr 30
A5: INVESTMENT SCHEDULE
A6: Initial / Maintenance Capex | B6: =Assumptions!B11 -> 625000000000 | C6: =Assumptions!B11 -> 625000000000 | H6: =Assumptions!B14 -> 12500000000 | M6: =Assumptions!B14 -> 12500000000 | R6: =Assumptions!B14 -> 12500000000 | W6: =Assumptions!B14 -> 12500000000 | AB6: =Assumptions!B14 -> 12500000000
A7: Salary (construction) | B7: =Assumptions!B22 -> 10000000000 | C7: =Assumptions!B24 -> 10350000000
A8: Total Construction Outflow | B8: =B6+B7 -> 635000000000 | C8: =C6+C7 -> 635350000000
A10: REVENUE
A11: Sugar Price per Tonne (IDR) | D11: =Assumptions!B28 -> 10000000 | E11: =D11*(1+Assumptions!B23) -> 10350000 | F11: =E11*(1+Assumptions!B23) -> 10712250 | G11: =F11*(1+Assumptions!B23) -> 11087179 | H11: =G11*(1+Assumptions!B23) -> 11475230 | I11: =H11*(1+Assumptions!B23) -> 11876863 | J11: =I11*(1+Assumptions!B23) -> 12292553 | K11: =J11*(1+Assumptions!B23) -> 12722793 | L11: =K11*(1+Assumptions!B23) -> 13168090 | M11: =L11*(1+Assumptions!B23) -> 13628974 | N11: =M11*(1+Assumptions!B23) -> 14105988 | O11: =N11*(1+Assumptions!B23) -> 14599697 | P11: =O11*(1+Assumptions!B23) -> 15110687 | Q11: =P11*(1+Assumptions!B23) -> 15639561 | R11: =Q11*(1+Assumptions!B23) -> 16186945 | S11: =R11*(1+Assumptions!B23) -> 16753488 | T11: =S11*(1+Assumptions!B23) -> 17339860 | U11: =T11*(1+Assumptions!B23) -> 17946756 | V11: =U11*(1+Assumptions!B23) -> 18574892 | W11: =V11*(1+Assumptions!B23) -> 19225013 | X11: =W11*(1+Assumptions!B23) -> 19897889 | Y11: =X11*(1+Assumptions!B23) -> 20594315 | Z11: =Y11*(1+Assumptions!B23) -> 21315116 | AA11: =Z11*(1+Assumptions!B23) -> 22061145 | AB11: =AA11*(1+Assumptions!B23) -> 22833285 | AC11: =AB11*(1+Assumptions!B23) -> 23632450 | AD11: =AC11*(1+Assumptions!B23) -> 24459586 | AE11: =AD11*(1+Assumptions!B23) -> 25315671 | AF11: =AE11*(1+Assumptions!B23) -> 26201720 | AG11: =AF11*(1+Assumptions!B23) -> 27118780
A12: Sales Volume (tonnes) | D12: =Assumptions!B29 -> 55000 | E12: =D12*(1+Assumptions!B31) -> 60775 | F12: =E12*(1+Assumptions!B31) -> 67156.375 | G12: =F12*(1+Assumptions!B31) -> 74207.794 | H12: =G12*(1+Assumptions!B31) -> 81999.613 | I12: =H12*(1+Assumptions!B31) -> 90609.572 | J12: =I12*(1+Assumptions!B31) -> 100123.58 | K12: =J12*(1+Assumptions!B31) -> 110636.55 | L12: =K12*(1+Assumptions!B31) -> 122253.39 | M12: =L12*(1+Assumptions!B31) -> 135090 | N12: =M12*(1+Assumptions!B31) -> 149274.45 | O12: =N12*(1+Assumptions!B31) -> 164948.26 | P12: =O12*(1+Assumptions!B31) -> 182267.83 | Q12: =P12*(1+Assumptions!B31) -> 201405.95 | R12: =Q12*(1+Assumptions!B31) -> 222553.58 | S12: =R12*(1+Assumptions!B31) -> 245921.7 | T12: =S12*(1+Assumptions!B31) -> 271743.48 | U12: =T12*(1+Assumptions!B31) -> 300276.55 | V12: =U12*(1+Assumptions!B31) -> 331805.59 | W12: =V12*(1+Assumptions!B31) -> 366645.17 | X12: =W12*(1+Assumptions!B31) -> 405142.92 | Y12: =X12*(1+Assumptions!B31) -> 447682.92 | Z12: =Y12*(1+Assumptions!B31) -> 494689.63 | AA12: =Z12*(1+Assumptions!B31) -> 546632.04 | AB12: =AA12*(1+Assumptions!B31) -> 604028.4 | AC12: =AB12*(1+Assumptions!B31) -> 667451.39 | AD12: =AC12*(1+Assumptions!B31) -> 737533.78 | AE12: =AD12*(1+Assumptions!B31) -> 814974.83 | AF12: =AE12*(1+Assumptions!B31) -> 900547.19 | AG12: =AF12*(1+Assumptions!B31) -> 995104.64
A13: Revenue | D13: =D11*D12 -> 550000000000 | E13: =E11*E12 -> 629021250000 | F13: =F11*F12 -> 7.1939588e+11 | G13: =G11*G12 -> 8.2275508e+11 | H13: =H11*H12 -> 9.4096442e+11 | I13: =I11*I12 -> 1.0761575e+12 | J13: =J11*J12 -> 1.2307744e+12 | K13: =K11*K12 -> 1.4076059e+12 | ... AG13: =AG11*AG12 -> 2.6986024e+13
A15: COST STRUCTURE
A16: EBITDA Margin | D16: =Assumptions!B34 -> 0.4 | E16: =Assumptions!B34 -> 0.4 | F16: =Assumptions!B34 -> 0.4 | G16: =Assumptions!B34 -> 0.4 | H16: =Assumptions!B34 -> 0.4 | I16: =Assumptions!B34 -> 0.4 | J16: =Assumptions!B34 -> 0.4 | K16: =Assumptions!B34 -> 0.4 | L16: =Assumptions!B34 -> 0.4 | M16: =Assumptions!B34 -> 0.4 | N16: =Assumptions!B34 -> 0.4 | O16: =Assumptions!B34 -> 0.4 | P16: =Assumptions!B34 -> 0.4 | Q16: =Assumptions!B34 -> 0.4 | R16: =Assumptions!B34 -> 0.4 | S16: =Assumptions!B34 -> 0.4 | T16: =Assumptions!B34 -> 0.4 | U16: =Assumptions!B34 -> 0.4 | V16: =Assumptions!B34 -> 0.4 | W16: =Assumptions!B34 -> 0.4 | X16: =Assumptions!B34 -> 0.4 | Y16: =Assumptions!B34 -> 0.4 | Z16: =Assumptions!B34 -> 0.4 | AA16: =Assumptions!B34 -> 0.4 | AB16: =Assumptions!B34 -> 0.4 | AC16: =Assumptions!B34 -> 0.4 | AD16: =Assumptions!B34 -> 0.4 | AE16: =Assumptions!B34 -> 0.4 | AF16: =Assumptions!B34 -> 0.4 | AG16: =Assumptions!B34 -> 0.4
A17: EBITDA | D17: =D13*D16 -> 220000000000 | E17: =E13*E16 -> 251608500000 | F17: =F13*F16 -> 2.8775835e+11 | G17: =G13*G16 -> 3.2910203e+11 | H17: =H13*H16 -> 3.7638577e+11 | I17: =I13*I16 -> 4.3046299e+11 | J17: =J13*J16 -> 4.9230976e+11 | K17: =K13*K16 -> 5.6304237e+11 | ... AG17: =AG13*AG16 -> 1.0794409e+13
A18: Fixed Cost | D18: =Assumptions!B35 -> 115000000000 | E18: =D18*(1+Assumptions!B23) -> 1.19025e+11 | F18: =E18*(1+Assumptions!B23) -> 1.2319087e+11 | G18: =F18*(1+Assumptions!B23) -> 1.2750256e+11 | H18: =G18*(1+Assumptions!B23) -> 1.3196515e+11 | I18: =H18*(1+Assumptions!B23) -> 1.3658393e+11 | J18: =I18*(1+Assumptions!B23) -> 1.4136436e+11 | K18: =J18*(1+Assumptions!B23) -> 1.4631212e+11 | L18: =K18*(1+Assumptions!B23) -> 1.5143304e+11 | M18: =L18*(1+Assumptions!B23) -> 1.567332e+11 | N18: =M18*(1+Assumptions!B23) -> 1.6221886e+11 | O18: =N18*(1+Assumptions!B23) -> 1.6789652e+11 | P18: =O18*(1+Assumptions!B23) -> 1.737729e+11 | Q18: =P18*(1+Assumptions!B23) -> 1.7985495e+11 | R18: =Q18*(1+Assumptions!B23) -> 1.8614987e+11 | S18: =R18*(1+Assumptions!B23) -> 1.9266512e+11 | T18: =S18*(1+Assumptions!B23) -> 1.9940839e+11 | U18: =T18*(1+Assumptions!B23) -> 2.0638769e+11 | V18: =U18*(1+Assumptions!B23) -> 2.1361126e+11 | W18: =V18*(1+Assumptions!B23) -> 2.2108765e+11 | X18: =W18*(1+Assumptions!B23) -> 2.2882572e+11 | Y18: =X18*(1+Assumptions!B23) -> 2.3683462e+11 | Z18: =Y18*(1+Assumptions!B23) -> 2.4512383e+11 | AA18: =Z18*(1+Assumptions!B23) -> 2.5370317e+11 | AB18: =AA18*(1+Assumptions!B23) -> 2.6258278e+11 | AC18: =AB18*(1+Assumptions!B23) -> 2.7177317e+11 | AD18: =AC18*(1+Assumptions!B23) -> 2.8128523e+11 | AE18: =AD18*(1+Assumptions!B23) -> 2.9113022e+11 | AF18: =AE18*(1+Assumptions!B23) -> 3.0131978e+11 | AG18: =AF18*(1+Assumptions!B23) -> 3.1186597e+11
A19: Variable Cost | D19: =D13*(1-D16)-D18 -> 215000000000 | E19: =E13*(1-E16)-E18 -> 258387750000 | F19: =F13*(1-F16)-F18 -> 3.0844665e+11 | G19: =G13*(1-G16)-G18 -> 3.6615049e+11 | H19: =H13*(1-H16)-H18 -> 4.3261351e+11 | I19: =I13*(1-I16)-I18 -> 5.0911056e+11 | J19: =J13*(1-J16)-J18 -> 5.9710028e+11 | K19: =K13*(1-K16)-K18 -> 6.9825144e+11 | ... AG19: =AG13*(1-AG16)-AG18 -> 1.5879748e+13
A20: Total Operating Cost | D20: =D18+D19 -> 330000000000 | E20: =E18+E19 -> 377412750000 | F20: =F18+F19 -> 4.3163753e+11 | G20: =G18+G19 -> 4.9365305e+11 | H20: =H18+H19 -> 5.6457865e+11 | I20: =I18+I19 -> 6.4569449e+11 | J20: =J18+J19 -> 7.3846464e+11 | K20: =K18+K19 -> 8.4456355e+11 | ... AG20: =AG18+AG19 -> 1.6191614e+13
A23: INCOME STATEMENT
A24: Depreciation | D24: =Assumptions!B19 -> 4.1666667e+10 | E24: =Assumptions!B19 -> 4.1666667e+10 | F24: =Assumptions!B19 -> 4.1666667e+10 | G24: =Assumptions!B19 -> 4.1666667e+10 | H24: =Assumptions!B19 -> 4.1666667e+10 | I24: =Assumptions!B19 -> 4.1666667e+10 | J24: =Assumptions!B19 -> 4.1666667e+10 | K24: =Assumptions!B19 -> 4.1666667e+10 | L24: =Assumptions!B19 -> 4.1666667e+10 | M24: =Assumptions!B19 -> 4.1666667e+10 | N24: =Assumptions!B19 -> 4.1666667e+10 | O24: =Assumptions!B19 -> 4.1666667e+10 | P24: =Assumptions!B19 -> 4.1666667e+10 | Q24: =Assumptions!B19 -> 4.1666667e+10 | R24: =Assumptions!B19 -> 4.1666667e+10 | S24: =Assumptions!B19 -> 4.1666667e+10 | T24: =Assumptions!B19 -> 4.1666667e+10 | U24: =Assumptions!B19 -> 4.1666667e+10 | V24: =Assumptions!B19 -> 4.1666667e+10 | W24: =Assumptions!B19 -> 4.1666667e+10 | X24: =Assumptions!B19 -> 4.1666667e+10 | Y24: =Assumptions!B19 -> 4.1666667e+10 | Z24: =Assumptions!B19 -> 4.1666667e+10 | AA24: =Assumptions!B19 -> 4.1666667e+10 | AB24: =Assumptions!B19 -> 4.1666667e+10 | AC24: =Assumptions!B19 -> 4.1666667e+10 | AD24: =Assumptions!B19 -> 4.1666667e+10 | AE24: =Assumptions!B19 -> 4.1666667e+10 | AF24: =Assumptions!B19 -> 4.1666667e+10 | AG24: =Assumptions!B19 -> 4.1666667e+10
A25: EBIT | D25: =D17-D24 -> 1.7833333e+11 | E25: =E17-E24 -> 2.0994183e+11 | F25: =F17-F24 -> 2.4609168e+11 | G25: =G17-G24 -> 2.8743537e+11 | H25: =H17-H24 -> 3.347191e+11 | I25: =I17-I24 -> 3.8879633e+11 | J25: =J17-J24 -> 4.506431e+11 | K25: =K17-K24 -> 5.213757e+11 | ... AG25: =AG17-AG24 -> 1.0752743e+13
A26: Interest Expense | D26: =D43 -> 93437500000 | E26: =E43 -> 8.7208333e+10 | F26: =F43 -> 8.0979167e+10 | G26: =G43 -> 7.475e+10 | H26: =H43 -> 6.8520833e+10 | I26: =I43 -> 6.2291667e+10 | J26: =J43 -> 5.60625e+10 | K26: =K43 -> 4.9833333e+10 | ... AG26: =AG43 -> 1.2283325e-05
A27: EBT (Earnings Before Tax) | D27: =D25-D26 -> 8.4895833e+10 | E27: =E25-E26 -> 122733500000 | F27: =F25-F26 -> 1.6511252e+11 | G27: =G25-G26 -> 2.1268537e+11 | H27: =H25-H26 -> 2.6619827e+11 | I27: =I25-I26 -> 3.2650466e+11 | J27: =J25-J26 -> 3.945806e+11 | K27: =K25-K26 -> 4.7154237e+11 | ... AG27: =AG25-AG26 -> 1.0752743e+13
A28: Tax (25%) | B28: 0 | C28: 0 | D28: =MAX(D27,0)*Assumptions!B42 -> 2.1223958e+10 | E28: =MAX(E27,0)*Assumptions!B42 -> 30683375000 | F28: =MAX(F27,0)*Assumptions!B42 -> 4.1278129e+10 | G28: =MAX(G27,0)*Assumptions!B42 -> 5.3171341e+10 | H28: =MAX(H27,0)*Assumptions!B42 -> 6.6549567e+10 | I28: =MAX(I27,0)*Assumptions!B42 -> 8.1626165e+10 | J28: =MAX(J27,0)*Assumptions!B42 -> 9.8645149e+10 | K28: =MAX(K27,0)*Assumptions!B42 -> 1.1788559e+11 | L28: =MAX(L27,0)*Assumptions!B42 -> 1.3966666e+11 | M28: =MAX(M27,0)*Assumptions!B42 -> 1.6435338e+11 | N28: =MAX(N27,0)*Assumptions!B42 -> 1.9236322e+11 | O28: =MAX(O27,0)*Assumptions!B42 -> 2.2417364e+11 | P28: =MAX(P27,0)*Assumptions!B42 -> 2.6033067e+11 | Q28: =MAX(Q27,0)*Assumptions!B42 -> 3.0145881e+11 | R28: =MAX(R27,0)*Assumptions!B42 -> 3.482723e+11 | S28: =MAX(S27,0)*Assumptions!B42 -> 4.0158797e+11 | T28: =MAX(T27,0)*Assumptions!B42 -> 4.6078274e+11 | U28: =MAX(U27,0)*Assumptions!B42 -> 5.2848231e+11 | V28: =MAX(V27,0)*Assumptions!B42 -> 6.0590863e+11 | W28: =MAX(W27,0)*Assumptions!B42 -> 6.9445916e+11 | X28: =MAX(X27,0)*Assumptions!B42 -> 7.957322e+11 | Y28: =MAX(Y27,0)*Assumptions!B42 -> 9.1155563e+11 | Z28: =MAX(Z27,0)*Assumptions!B42 -> 1.04402e+12 | AA28: =MAX(AA27,0)*Assumptions!B42 -> 1.1955162e+12 | AB28: =MAX(AB27,0)*Assumptions!B42 -> 1.3687786e+12 | AC28: =MAX(AC27,0)*Assumptions!B42 -> 1.5669345e+12 | AD28: =MAX(AD27,0)*Assumptions!B42 -> 1.7935604e+12 | AE28: =MAX(AE27,0)*Assumptions!B42 -> 2.0527468e+12 | AF28: =MAX(AF27,0)*Assumptions!B42 -> 2.3491718e+12 | AG28: =MAX(AG27,0)*Assumptions!B42 -> 2.6881857e+12
A29: Net Income | D29: =D27-D28 -> 6.3671875e+10 | E29: =E27-E28 -> 92050125000 | F29: =F27-F28 -> 1.2383439e+11 | G29: =G27-G28 -> 1.5951402e+11 | H29: =H27-H28 -> 1.996487e+11 | I29: =I27-I28 -> 2.4487849e+11 | J29: =J27-J28 -> 2.9593545e+11 | K29: =K27-K28 -> 3.5365678e+11 | ... AG29: =AG27-AG28 -> 8.0645571e+12
A31: FREE CASH FLOW
A32: Net Income | D32: =D29 -> 6.3671875e+10 | E32: =E29 -> 92050125000 | F32: =F29 -> 1.2383439e+11 | G32: =G29 -> 1.5951402e+11 | H32: =H29 -> 1.996487e+11 | I32: =I29 -> 2.4487849e+11 | J32: =J29 -> 2.9593545e+11 | K32: =K29 -> 3.5365678e+11 | ... AG32: =AG29 -> 8.0645571e+12
A33: Add: Depreciation | D33: =D24 -> 4.1666667e+10 | E33: =E24 -> 4.1666667e+10 | F33: =F24 -> 4.1666667e+10 | G33: =G24 -> 4.1666667e+10 | H33: =H24 -> 4.1666667e+10 | I33: =I24 -> 4.1666667e+10 | J33: =J24 -> 4.1666667e+10 | K33: =K24 -> 4.1666667e+10 | ... AG33: =AG24 -> 4.1666667e+10
A34: Less: Maintenance Capex | D34: 0 | E34: 0 | F34: 0 | G34: 0 | H34: =-Assumptions!B14 -> -12500000000 | I34: 0 | J34: 0 | K34: 0 | L34: 0 | M34: =-Assumptions!B14 -> -12500000000 | N34: 0 | O34: 0 | P34: 0 | Q34: 0 | R34: =-Assumptions!B14 -> -12500000000 | S34: 0 | T34: 0 | U34: 0 | V34: 0 | W34: =-Assumptions!B14 -> -12500000000 | X34: 0 | Y34: 0 | Z34: 0 | AA34: 0 | AB34: =-Assumptions!B14 -> -12500000000 | AC34: 0 | AD34: 0 | AE34: 0 | AF34: 0 | AG34: 0
A35: Less: Forgone Net Cash Flow | B35: =-Assumptions!B39 -> -50000000000 | C35: =-Assumptions!B39 -> -50000000000 | D35: =-Assumptions!B39 -> -50000000000 | E35: =-Assumptions!B39 -> -50000000000 | F35: =-Assumptions!B39 -> -50000000000 | G35: =-Assumptions!B39 -> -50000000000 | H35: =-Assumptions!B39 -> -50000000000 | I35: =-Assumptions!B39 -> -50000000000 | J35: =-Assumptions!B39 -> -50000000000 | K35: =-Assumptions!B39 -> -50000000000 | L35: =-Assumptions!B39 -> -50000000000 | M35: =-Assumptions!B39 -> -50000000000 | N35: =-Assumptions!B39 -> -50000000000 | O35: =-Assumptions!B39 -> -50000000000 | P35: =-Assumptions!B39 -> -50000000000 | Q35: =-Assumptions!B39 -> -50000000000 | R35: =-Assumptions!B39 -> -50000000000 | S35: =-Assumptions!B39 -> -50000000000 | T35: =-Assumptions!B39 -> -50000000000 | U35: =-Assumptions!B39 -> -50000000000 | V35: =-Assumptions!B39 -> -50000000000 | W35: =-Assumptions!B39 -> -50000000000 | X35: =-Assumptions!B39 -> -50000000000 | Y35: =-Assumptions!B39 -> -50000000000 | Z35: =-Assumptions!B39 -> -50000000000 | AA35: =-Assumptions!B39 -> -50000000000 | AB35: =-Assumptions!B39 -> -50000000000 | AC35: =-Assumptions!B39 -> -50000000000 | AD35: =-Assumptions!B39 -> -50000000000 | AE35: =-Assumptions!B39 -> -50000000000 | AF35: =-Assumptions!B39 -> -50000000000 | AG35: =-Assumptions!B39 -> -50000000000
A36: Salvage Value (year 30) | AG36: =Assumptions!B10-Assumptions!B19*Assumptions!B6 -> 0
A37: Less: Construction Outflow | B37: =-B8 -> -635000000000 | C37: =-C8 -> -635350000000
A38: FREE CASH FLOW | B38: =B37+B35 -> -685000000000 | C38: =C37+C35 -> -685350000000 | D38: =D32+D33+D34+D35+D36 -> 5.5338542e+10 | E38: =E32+E33+E34+E35+E36 -> 8.3716792e+10 | F38: =F32+F33+F34+F35+F36 -> 1.1550106e+11 | G38: =G32+G33+G34+G35+G36 -> 1.5118069e+11 | H38: =H32+H33+H34+H35+H36 -> 1.7881537e+11 | I38: =I32+I33+I34+I35+I36 -> 2.3654516e+11 | J38: =J32+J33+J34+J35+J36 -> 2.8760211e+11 | K38: =K32+K33+K34+K35+K36 -> 3.4532344e+11 | ... AG38: =AG32+AG33+AG34+AG35+AG36 -> 8.0562238e+12
A40: DEBT SCHEDULE
A41: Debt Balance (start of year) | D41: =Assumptions!B10*Assumptions!B46 -> 812500000000 | E41: =MAX(D41-D42,0) -> 7.5833333e+11 | F41: =MAX(E41-E42,0) -> 7.0416667e+11 | G41: =MAX(F41-F42,0) -> 6.5e+11 | H41: =MAX(G41-G42,0) -> 5.9583333e+11 | I41: =MAX(H41-H42,0) -> 5.4166667e+11 | J41: =MAX(I41-I42,0) -> 4.875e+11 | K41: =MAX(J41-J42,0) -> 4.3333333e+11 | L41: =MAX(K41-K42,0) -> 3.7916667e+11 | ... AG41: =MAX(AF41-AF42,0) -> 0.00010681152
A42: Sinking Fund (annual repayment) | D42: =Assumptions!B10*Assumptions!B46/Assumptions!B50 -> 5.4166667e+10 | E42: =Assumptions!B10*Assumptions!B46/Assumptions!B50 -> 5.4166667e+10 | F42: =Assumptions!B10*Assumptions!B46/Assumptions!B50 -> 5.4166667e+10 | G42: =Assumptions!B10*Assumptions!B46/Assumptions!B50 -> 5.4166667e+10 | H42: =Assumptions!B10*Assumptions!B46/Assumptions!B50 -> 5.4166667e+10 | I42: =Assumptions!B10*Assumptions!B46/Assumptions!B50 -> 5.4166667e+10 | J42: =Assumptions!B10*Assumptions!B46/Assumptions!B50 -> 5.4166667e+10 | K42: =Assumptions!B10*Assumptions!B46/Assumptions!B50 -> 5.4166667e+10 | L42: =Assumptions!B10*Assumptions!B46/Assumptions!B50 -> 5.4166667e+10 | M42: =Assumptions!B10*Assumptions!B46/Assumptions!B50 -> 5.4166667e+10 | N42: =Assumptions!B10*Assumptions!B46/Assumptions!B50 -> 5.4166667e+10 | O42: =Assumptions!B10*Assumptions!B46/Assumptions!B50 -> 5.4166667e+10 | P42: =Assumptions!B10*Assumptions!B46/Assumptions!B50 -> 5.4166667e+10 | Q42: =Assumptions!B10*Assumptions!B46/Assumptions!B50 -> 5.4166667e+10 | R42: =Assumptions!B10*Assumptions!B46/Assumptions!B50 -> 5.4166667e+10 | S42: 0 | T42: 0 | U42: 0 | V42: 0 | W42: 0 | X42: 0 | Y42: 0 | Z42: 0 | AA42: 0 | AB42: 0 | AC42: 0 | AD42: 0 | AE42: 0 | AF42: 0 | AG42: 0
A43: Interest Expense | D43: =D41*Assumptions!B48 -> 93437500000 | E43: =E41*Assumptions!B48 -> 8.7208333e+10 | F43: =F41*Assumptions!B48 -> 8.0979167e+10 | G43: =G41*Assumptions!B48 -> 7.475e+10 | H43: =H41*Assumptions!B48 -> 6.8520833e+10 | I43: =I41*Assumptions!B48 -> 6.2291667e+10 | J43: =J41*Assumptions!B48 -> 5.60625e+10 | K43: =K41*Assumptions!B48 -> 4.9833333e+10 | L43: =L41*Assumptions!B48 -> 4.3604167e+10 | M43: =M41*Assumptions!B48 -> 3.7375e+10 | N43: =N41*Assumptions!B48 -> 3.1145833e+10 | O43: =O41*Assumptions!B48 -> 2.4916667e+10 | P43: =P41*Assumptions!B48 -> 1.86875e+10 | Q43: =Q41*Assumptions!B48 -> 1.2458333e+10 | R43: =R41*Assumptions!B48 -> 6.2291667e+09 | S43: =S41*Assumptions!B48 -> 1.2283325e-05 | T43: =T41*Assumptions!B48 -> 1.2283325e-05 | U43: =U41*Assumptions!B48 -> 1.2283325e-05 | V43: =V41*Assumptions!B48 -> 1.2283325e-05 | W43: =W41*Assumptions!B48 -> 1.2283325e-05 | X43: =X41*Assumptions!B48 -> 1.2283325e-05 | Y43: =Y41*Assumptions!B48 -> 1.2283325e-05 | Z43: =Z41*Assumptions!B48 -> 1.2283325e-05 | AA43: =AA41*Assumptions!B48 -> 1.2283325e-05 | AB43: =AB41*Assumptions!B48 -> 1.2283325e-05 | AC43: =AC41*Assumptions!B48 -> 1.2283325e-05 | AD43: =AD41*Assumptions!B48 -> 1.2283325e-05 | AE43: =AE41*Assumptions!B48 -> 1.2283325e-05 | AF43: =AF41*Assumptions!B48 -> 1.2283325e-05 | AG43: =AG41*Assumptions!B48 -> 1.2283325e-05

Sheet NPV Analysis
A1: NPV ANALYSIS
B2: Const 1 | C2: Const 2 | D2: Op Yr 1 | E2: Op Yr 2 | F2: Op Yr 3 | G2: Op Yr 4 | H2: Op Yr 5 | I2: Op Yr 6 | J2: Op Yr 7 | K2: Op Yr 8 | L2: Op Yr 9 | M2: Op Yr 10 | N2: Op Yr 11 | O2: Op Yr 12 | P2: Op Yr 13 | Q2: Op Yr 14 | R2: Op Yr 15 | S2: Op Yr 16 | T2: Op Yr 17 | U2: Op Yr 18 | V2: Op Yr 19 | W2: Op Yr 20 | X2: Op Yr 21 | Y2: Op Yr 22 | Z2: Op Yr 23 | AA2: Op Yr 24 | AB2: Op Yr 25 | AC2: Op Yr 26 | AD2: Op Yr 27 | AE2: Op Yr 28 | AF2: Op Yr 29 | AG2: Op Yr 30
A3: Period | B3: 0 | C3: 1 | D3: 2 | E3: 3 | F3: 4 | G3: 5 | H3: 6 | I3: 7 | J3: 8 | K3: 9 | L3: 10 | M3: 11 | N3: 12 | O3: 13 | P3: 14 | Q3: 15 | R3: 16 | S3: 17 | T3: 18 | U3: 19 | V3: 20 | W3: 21 | X3: 22 | Y3: 23 | Z3: 24 | AA3: 25 | AB3: 26 | AC3: 27 | AD3: 28 | AE3: 29 | AF3: 30 | AG3: 31
A4: Free Cash Flow | B4: ='Income & Cash Flow'!B38 -> -685000000000 | C4: ='Income & Cash Flow'!C38 -> -685350000000 | D4: ='Income & Cash Flow'!D38 -> 5.5338542e+10 | E4: ='Income & Cash Flow'!E38 -> 8.3716792e+10 | F4: ='Income & Cash Flow'!F38 -> 1.1550106e+11 | G4: ='Income & Cash Flow'!G38 -> 1.5118069e+11 | H4: ='Income & Cash Flow'!H38 -> 1.7881537e+11 | I4: ='Income & Cash Flow'!I38 -> 2.3654516e+11 | ... AG4: ='Income & Cash Flow'!AG38 -> 8.0562238e+12
A5: Discount Factor (r=WACC+1%) | B5: =1/(1+WACC!B17)^B3 -> 1 | C5: =1/(1+WACC!B17)^C3 -> 0.89375489 | D5: =1/(1+WACC!B17)^D3 -> 0.7987978 | E5: =1/(1+WACC!B17)^E3 -> 0.71392944 | F5: =1/(1+WACC!B17)^F3 -> 0.63807792 | G5: =1/(1+WACC!B17)^G3 -> 0.57028526 | H5: =1/(1+WACC!B17)^H3 -> 0.50969524 | I5: =1/(1+WACC!B17)^I3 -> 0.45554261 | J5: =1/(1+WACC!B17)^J3 -> 0.40714344 | K5: =1/(1+WACC!B17)^K3 -> 0.36388644 | L5: =1/(1+WACC!B17)^L3 -> 0.32522528 | M5: =1/(1+WACC!B17)^M3 -> 0.29067169 | N5: =1/(1+WACC!B17)^N3 -> 0.25978924 | O5: =1/(1+WACC!B17)^O3 -> 0.2321879 | P5: =1/(1+WACC!B17)^P3 -> 0.20751907 | Q5: =1/(1+WACC!B17)^Q3 -> 0.18547119 | R5: =1/(1+WACC!B17)^R3 -> 0.16576578 | S5: =1/(1+WACC!B17)^S3 -> 0.14815397 | T5: =1/(1+WACC!B17)^T3 -> 0.13241334 | U5: =1/(1+WACC!B17)^U3 -> 0.11834507 | V5: =1/(1+WACC!B17)^V3 -> 0.10577148 | W5: =1/(1+WACC!B17)^W3 -> 0.094533781 | X5: =1/(1+WACC!B17)^X3 -> 0.084490029 | Y5: =1/(1+WACC!B17)^Y3 -> 0.075513376 | Z5: =1/(1+WACC!B17)^Z3 -> 0.067490449 | AA5: =1/(1+WACC!B17)^AA3 -> 0.060319919 | AB5: =1/(1+WACC!B17)^AB3 -> 0.053911222 | AC5: =1/(1+WACC!B17)^AC3 -> 0.048183418 | AD5: =1/(1+WACC!B17)^AD3 -> 0.043064166 | AE5: =1/(1+WACC!B17)^AE3 -> 0.038488808 | AF5: =1/(1+WACC!B17)^AF3 -> 0.034399561 | AG5: =1/(1+WACC!B17)^AG3 -> 0.030744775
A6: PV of FCF | B6: =B4*B5 -> -685000000000 | C6: =C4*C5 -> -6.1253491e+11 | D6: =D4*D5 -> 4.4204305e+10 | E6: =E4*E5 -> 5.9767882e+10 | F6: =F4*F5 -> 7.3698673e+10 | G6: =G4*G5 -> 8.621612e+10 | H6: =H4*H5 -> 9.1141342e+10 | I6: =I4*I5 -> 1.077564e+11 | ... AG6: =AG4*AG5 -> 2.4768679e+11
A8: SUMMARY
A9: WACC | B9: =WACC!B16 -> 0.108875
A10: Required Rate (WACC+1%) | B10: =WACC!B17 -> 0.118875
A11: Sum of PV (all periods) | B11: =SUM(B6:AI6) -> 3.6470394e+12
A12: NPV | B12: =SUM(B6:AG6) -> 3.6470394e+12
A14: Interpretation:
A15: =IF(B12>0,"NPV is POSITIVE → Project ACCEPTED (creates value)","NPV is NEGATIVE → Project REJECTED (destroys value)") -> NPV is POSITIVE → Project ACCEPTED (creates value)

Sheet Break-Even & DOL
A1: BREAK-EVEN & DEGREE OF OPERATING LEVERAGE (DOL)
B2: Const 1 | C2: Const 2 | D2: Op Yr 1 | E2: Op Yr 2 | F2: Op Yr 3 | G2: Op Yr 4 | H2: Op Yr 5 | I2: Op Yr 6 | J2: Op Yr 7 | K2: Op Yr 8 | L2: Op Yr 9 | M2: Op Yr 10 | N2: Op Yr 11 | O2: Op Yr 12 | P2: Op Yr 13 | Q2: Op Yr 14 | R2: Op Yr 15 | S2: Op Yr 16 | T2: Op Yr 17 | U2: Op Yr 18 | V2: Op Yr 19 | W2: Op Yr 20 | X2: Op Yr 21 | Y2: Op Yr 22 | Z2: Op Yr 23 | AA2: Op Yr 24 | AB2: Op Yr 25 | AC2: Op Yr 26 | AD2: Op Yr 27 | AE2: Op Yr 28 | AF2: Op Yr 29 | AG2: Op Yr 30
A3: Revenue | B3: ='Income & Cash Flow'!B13 -> 0 | C3: ='Income & Cash Flow'!C13 -> 0 | D3: ='Income & Cash Flow'!D13 -> 550000000000 | E3: ='Income & Cash Flow'!E13 -> 629021250000 | F3: ='Income & Cash Flow'!F13 -> 7.1939588e+11 | G3: ='Income & Cash Flow'!G13 -> 8.2275508e+11 | H3: ='Income & Cash Flow'!H13 -> 9.4096442e+11 | I3: ='Income & Cash Flow'!I13 -> 1.0761575e+12 | ... AG3: ='Income & Cash Flow'!AG13 -> 2.6986024e+13
A4: Fixed Cost | B4: ='Income & Cash Flow'!B18 -> 0 | C4: ='Income & Cash Flow'!C18 -> 0 | D4: ='Income & Cash Flow'!D18 -> 115000000000 | E4: ='Income & Cash Flow'!E18 -> 1.19025e+11 | F4: ='Income & Cash Flow'!F18 -> 1.2319087e+11 | G4: ='Income & Cash Flow'!G18 -> 1.2750256e+11 | H4: ='Income & Cash Flow'!H18 -> 1.3196515e+11 | I4: ='Income & Cash Flow'!I18 -> 1.3658393e+11 | ... AG4: ='Income & Cash Flow'!AG18 -> 3.1186597e+11
A5: Variable Cost | B5: ='Income & Cash Flow'!B19 -> 0 | C5: ='Income & Cash Flow'!C19 -> 0 | D5: ='Income & Cash Flow'!D19 -> 215000000000 | E5: ='Income & Cash Flow'!E19 -> 258387750000 | F5: ='Income & Cash Flow'!F19 -> 3.0844665e+11 | G5: ='Income & Cash Flow'!G19 -> 3.6615049e+11 | H5: ='Income & Cash Flow'!H19 -> 4.3261351e+11 | I5: ='Income & Cash Flow'!I19 -> 5.0911056e+11 | ... AG5: ='Income & Cash Flow'!AG19 -> 1.5879748e+13
A6: Total Cost | B6: ='Income & Cash Flow'!B20 -> 0 | C6: ='Income & Cash Flow'!C20 -> 0 | D6: ='Income & Cash Flow'!D20 -> 330000000000 | E6: ='Income & Cash Flow'!E20 -> 377412750000 | F6: ='Income & Cash Flow'!F20 -> 4.3163753e+11 | G6: ='Income & Cash Flow'!G20 -> 4.9365305e+11 | H6: ='Income & Cash Flow'!H20 -> 5.6457865e+11 | I6: ='Income & Cash Flow'!I20 -> 6.4569449e+11 | ... AG6: ='Income & Cash Flow'!AG20 -> 1.6191614e+13
A7: Depreciation | B7: ='Income & Cash Flow'!B24 -> 0 | C7: ='Income & Cash Flow'!C24 -> 0 | D7: ='Income & Cash Flow'!D24 -> 4.1666667e+10 | E7: ='Income & Cash Flow'!E24 -> 4.1666667e+10 | F7: ='Income & Cash Flow'!F24 -> 4.1666667e+10 | G7: ='Income & Cash Flow'!G24 -> 4.1666667e+10 | H7: ='Income & Cash Flow'!H24 -> 4.1666667e+10 | I7: ='Income & Cash Flow'!I24 -> 4.1666667e+10 | ... AG7: ='Income & Cash Flow'!AG24 -> 4.1666667e+10
A8: EBIT | B8: ='Income & Cash Flow'!B25 -> 0 | C8: ='Income & Cash Flow'!C25 -> 0 | D8: ='Income & Cash Flow'!D25 -> 1.7833333e+11 | E8: ='Income & Cash Flow'!E25 -> 2.0994183e+11 | F8: ='Income & Cash Flow'!F25 -> 2.4609168e+11 | G8: ='Income & Cash Flow'!G25 -> 2.8743537e+11 | H8: ='Income & Cash Flow'!H25 -> 3.347191e+11 | I8: ='Income & Cash Flow'!I25 -> 3.8879633e+11 | ... AG8: ='Income & Cash Flow'!AG25 -> 1.0752743e+13
A9: Sales Volume (Q) | B9: ='Income & Cash Flow'!B12 -> 0 | C9: ='Income & Cash Flow'!C12 -> 0 | D9: ='Income & Cash Flow'!D12 -> 55000 | E9: ='Income & Cash Flow'!E12 -> 60775 | F9: ='Income & Cash Flow'!F12 -> 67156.375 | G9: ='Income & Cash Flow'!G12 -> 74207.794 | H9: ='Income & Cash Flow'!H12 -> 81999.613 | I9: ='Income & Cash Flow'!I12 -> 90609.572 | ... AG9: ='Income & Cash Flow'!AG12 -> 995104.64
A10: Price per Tonne | B10: ='Income & Cash Flow'!B11 -> 0 | C10: ='Income & Cash Flow'!C11 -> 0 | D10: ='Income & Cash Flow'!D11 -> 10000000 | E10: ='Income & Cash Flow'!E11 -> 10350000 | F10: ='Income & Cash Flow'!F11 -> 10712250 | G10: ='Income & Cash Flow'!G11 -> 11087179 | H10: ='Income & Cash Flow'!H11 -> 11475230 | I10: ='Income & Cash Flow'!I11 -> 11876863 | ... AG10: ='Income & Cash Flow'!AG11 -> 27118780
A11: COST PER UNIT
A12: Variable Cost per Unit (VC/Q) | D12: =IF('Income & Cash Flow'!D12=0,0,'Income & Cash Flow'!D19/'Income & Cash Flow'!D12) -> 3909090.9 | E12: =IF('Income & Cash Flow'!E12=0,0,'Income & Cash Flow'!E19/'Income & Cash Flow'!E12) -> 4251546.7 | F12: =IF('Income & Cash Flow'!F12=0,0,'Income & Cash Flow'!F19/'Income & Cash Flow'!F12) -> 4592961.6 | G12: =IF('Income & Cash Flow'!G12=0,0,'Income & Cash Flow'!G19/'Income & Cash Flow'!G12) -> 4934124.5 | H12: =IF('Income & Cash Flow'!H12=0,0,'Income & Cash Flow'!H19/'Income & Cash Flow'!H12) -> 5275799.4 | I12: =IF('Income & Cash Flow'!I12=0,0,'Income & Cash Flow'!I19/'Income & Cash Flow'!I12) -> 5618728.3 | J12: =IF('Income & Cash Flow'!J12=0,0,'Income & Cash Flow'!J19/'Income & Cash Flow'!J12) -> 5963633.1 | K12: =IF('Income & Cash Flow'!K12=0,0,'Income & Cash Flow'!K19/'Income & Cash Flow'!K12) -> 6311218.3 | ... AG12: =IF('Income & Cash Flow'!AG12=0,0,'Income & Cash Flow'!AG19/'Income & Cash Flow'!AG12) -> 15957868
A13: Contribution Margin per Unit | D13: ='Income & Cash Flow'!D11-D12 -> 6090909.1 | E13: ='Income & Cash Flow'!E11-E12 -> 6098453.3 | F13: ='Income & Cash Flow'!F11-F12 -> 6119288.4 | G13: ='Income & Cash Flow'!G11-G12 -> 6153054.3 | H13: ='Income & Cash Flow'!H11-H12 -> 6199430.6 | I13: ='Income & Cash Flow'!I11-I12 -> 6258134.8 | J13: ='Income & Cash Flow'!J11-J12 -> 6328920.1 | K13: ='Income & Cash Flow'!K11-K12 -> 6411574.3 | ... AG13: ='Income & Cash Flow'!AG11-AG12 -> 11160912
A15: ACCOUNTING BREAK-EVEN (Q where Net Income = 0) = (FC + D)/(p - v)
A16: Acctg BE Qty (tonnes) | D16: =IF(D13=0,0,('Income & Cash Flow'!D18+'Income & Cash Flow'!D24)/D13) -> 25721.393 | E16: =IF(E13=0,0,('Income & Cash Flow'!E18+'Income & Cash Flow'!E24)/E13) -> 26349.577 | F16: =IF(F13=0,0,('Income & Cash Flow'!F18+'Income & Cash Flow'!F24)/F13) -> 26940.639 | G16: =IF(G13=0,0,('Income & Cash Flow'!G18+'Income & Cash Flow'!G24)/G13) -> 27493.536 | H16: =IF(H13=0,0,('Income & Cash Flow'!H18+'Income & Cash Flow'!H24)/H13) -> 28007.703 | I16: =IF(I13=0,0,('Income & Cash Flow'!I18+'Income & Cash Flow'!I24)/I13) -> 28483.022 | J16: =IF(J13=0,0,('Income & Cash Flow'!J18+'Income & Cash Flow'!J24)/J13) -> 28919.788 | K16: =IF(K13=0,0,('Income & Cash Flow'!K18+'Income & Cash Flow'!K24)/K13) -> 29318.662 | ... AG16: =IF(AG13=0,0,('Income & Cash Flow'!AG18+'Income & Cash Flow'!AG24)/AG13) -> 31675.963
A17: Acctg BE Revenue | D17: =D16*'Income & Cash Flow'!D11 -> 2.5721393e+11 | E17: =E16*'Income & Cash Flow'!E11 -> 2.7271812e+11 | F17: =F16*'Income & Cash Flow'!F11 -> 2.8859486e+11 | G17: =G16*'Income & Cash Flow'!G11 -> 3.0482575e+11 | H17: =H16*'Income & Cash Flow'!H11 -> 3.2139483e+11 | I17: =I16*'Income & Cash Flow'!I11 -> 3.3828895e+11 | J17: =J16*'Income & Cash Flow'!J11 -> 3.5549803e+11 | K17: =K16*'Income & Cash Flow'!K11 -> 3.7301526e+11 | ... AG17: =AG16*'Income & Cash Flow'!AG11 -> 8.5901345e+11
A19: CASH BREAK-EVEN (Q where OCF = 0, excluding non-cash dep) = FC/(p - v)
A20: Cash BE Qty (tonnes) | D20: =IF(D13=0,0,'Income & Cash Flow'!D18/D13) -> 18880.597 | E20: =IF(E13=0,0,'Income & Cash Flow'!E18/E13) -> 19517.244 | F20: =IF(F13=0,0,'Income & Cash Flow'!F18/F13) -> 20131.569 | G20: =IF(G13=0,0,'Income & Cash Flow'!G18/G13) -> 20721.832 | H20: =IF(H13=0,0,'Income & Cash Flow'!H18/H13) -> 21286.656 | I20: =IF(I13=0,0,'Income & Cash Flow'!I18/I13) -> 21825.021 | J20: =IF(J13=0,0,'Income & Cash Flow'!J18/J13) -> 22336.253 | K20: =IF(K13=0,0,'Income & Cash Flow'!K18/K13) -> 22819.998 | ... AG20: =IF(AG13=0,0,'Income & Cash Flow'!AG18/AG13) -> 27942.695
A21: Cash BE Revenue | D21: =D20*'Income & Cash Flow'!D11 -> 1.8880597e+11 | E21: =E20*'Income & Cash Flow'!E11 -> 2.0200347e+11 | F21: =F20*'Income & Cash Flow'!F11 -> 2.156544e+11 | G21: =G20*'Income & Cash Flow'!G11 -> 2.2974665e+11 | H21: =H20*'Income & Cash Flow'!H11 -> 2.4426927e+11 | I21: =I20*'Income & Cash Flow'!I11 -> 2.5921279e+11 | J21: =J20*'Income & Cash Flow'!J11 -> 2.7456958e+11 | K21: =K20*'Income & Cash Flow'!K11 -> 2.9033411e+11 | ... AG21: =AG20*'Income & Cash Flow'!AG11 -> 7.577718e+11
A23: DEGREE OF OPERATING LEVERAGE (DOL)
A24: Contribution Margin (total) | D24: ='Income & Cash Flow'!D13-'Income & Cash Flow'!D19 -> 335000000000 | E24: ='Income & Cash Flow'!E13-'Income & Cash Flow'!E19 -> 370633500000 | F24: ='Income & Cash Flow'!F13-'Income & Cash Flow'!F19 -> 4.1094923e+11 | G24: ='Income & Cash Flow'!G13-'Income & Cash Flow'!G19 -> 4.5660459e+11 | H24: ='Income & Cash Flow'!H13-'Income & Cash Flow'!H19 -> 5.0835091e+11 | I24: ='Income & Cash Flow'!I13-'Income & Cash Flow'!I19 -> 5.6704692e+11 | J24: ='Income & Cash Flow'!J13-'Income & Cash Flow'!J19 -> 6.3367412e+11 | K24: ='Income & Cash Flow'!K13-'Income & Cash Flow'!K19 -> 7.0935448e+11 | ... AG24: ='Income & Cash Flow'!AG13-'Income & Cash Flow'!AG19 -> 1.1106275e+13
A25: DOL = CM / EBIT | D25: =IF('Income & Cash Flow'!D25=0,"-",D24/'Income & Cash Flow'!D25) -> 1.8785047 | E25: =IF('Income & Cash Flow'!E25=0,"-",E24/'Income & Cash Flow'!E25) -> 1.7654104 | F25: =IF('Income & Cash Flow'!F25=0,"-",F24/'Income & Cash Flow'!F25) -> 1.6699029 | G25: =IF('Income & Cash Flow'!G25=0,"-",G24/'Income & Cash Flow'!G25) -> 1.588547 | H25: =IF('Income & Cash Flow'!H25=0,"-",H24/'Income & Cash Flow'!H25) -> 1.5187389 | I25: =IF('Income & Cash Flow'!I25=0,"-",I24/'Income & Cash Flow'!I25) -> 1.4584678 | J25: =IF('Income & Cash Flow'!J25=0,"-",J24/'Income & Cash Flow'!J25) -> 1.4061552 | K25: =IF('Income & Cash Flow'!K25=0,"-",K24/'Income & Cash Flow'!K25) -> 1.3605438 | ... AG25: =IF('Income & Cash Flow'!AG25=0,"-",AG24/'Income & Cash Flow'!AG25) -> 1.0328784
A27: FINANCIAL BREAK-EVEN (Q where NPV = 0 — use Goal Seek/Solver on NPV sheet)
A28: Financial BE is the volume in Year 1 (Op Yr 1) where NPV = 0. Use Goal Seek: Set NPV!B12 = 0 By Changing: 'Income & Cash Flow'!D13 (Revenue Yr1) Then back-calculate: Q_fin_BE = Revenue_BE / Price_Yr1

Sheet Summary Dashboard
A1: SUMMARY — Company A Sugar Processing Plant
A3: PROJECT PARAMETERS
A4: Total Investment | B4: =Assumptions!B10 -> 1250000000000
A5: Project Tenure | B5: =Assumptions!B6&" years" -> 30 years
A6: Inflation Rate | B6: =Assumptions!B23 -> 0.035
A7: Sales Growth (real) | B7: =Assumptions!B30 -> 0.07
A8: EBITDA Margin | B8: =Assumptions!B34 -> 0.4
A10: FINANCING
A11: Debt Proportion | B11: =Assumptions!B46 -> 0.65
A12: Equity Proportion | B12: =Assumptions!B47 -> 0.35
A13: Bond Coupon Rate | B13: =Assumptions!B48 -> 0.115
A14: Unlevered Cost of Equity | B14: =Assumptions!B51 -> 0.13
A15: Levered Cost of Equity | B15: =WACC!B13 -> 0.15089286
A16: WACC | B16: =WACC!B16 -> 0.108875
A17: Required Rate (WACC+1%) | B17: =WACC!B17 -> 0.118875
A19: PROJECT VALUATION
A20: NPV | B20: ='NPV Analysis'!B12 -> 3.6470394e+12
A21: Project Decision | B21: ='NPV Analysis'!A15 -> NPV is POSITIVE → Project ACCEPTED (creates value)
A23: YEAR 1 OPERATION METRICS
A24: Revenue (Op Yr 1) | B24: ='Income & Cash Flow'!D13 -> 550000000000
A25: EBITDA (Op Yr 1) | B25: ='Income & Cash Flow'!D17 -> 220000000000
A26: Net Income (Op Yr 1) | B26: ='Income & Cash Flow'!D29 -> 6.3671875e+10
A27: FCF (Op Yr 1) | B27: ='Income & Cash Flow'!D38 -> 5.5338542e+10
A28: Acctg BE Qty (Op Yr 1) | B28: ='Break-Even & DOL'!D16 -> 25721.393
A29: Cash BE Qty (Op Yr 1) | B29: ='Break-Even & DOL'!D20 -> 18880.597
A30: DOL (Op Yr 1) | B30: ='Break-Even & DOL'!D25 -> 1.8785047

Sheet SML
C2: rf | D2: 0.065
C3: beta | D3: 1.375
C4: rp | D4: 0.18
C5: slope | D5: =(D4-D2)/D3 -> 0.083636364 | E5: -- reward to risk ratio
C8: beta | D8: 2
C9: rp | D9: =D2+D8*D5 -> 0.23227273
B12: beta | C12: rate
B13: 0 | C13: =D2 -> 0.065
B14: =(C14-$C$13)/$D$5 -> 0.059782609 | C14: =C13+0.5% -> 0.07
B15: =(C15-$C$13)/$D$5 -> 0.11956522 | C15: =C14+0.5% -> 0.075
B16: =(C16-$C$13)/$D$5 -> 0.17934783 | C16: =C15+0.5% -> 0.08
B17: =(C17-$C$13)/$D$5 -> 0.23913043 | C17: =C16+0.5% -> 0.085
B18: =(C18-$C$13)/$D$5 -> 0.29891304 | C18: =C17+0.5% -> 0.09
B19: =(C19-$C$13)/$D$5 -> 0.35869565 | C19: =C18+0.5% -> 0.095
B20: =(C20-$C$13)/$D$5 -> 0.41847826 | C20: =C19+0.5% -> 0.1
B21: =(C21-$C$13)/$D$5 -> 0.47826087 | C21: =C20+0.5% -> 0.105
B22: =(C22-$C$13)/$D$5 -> 0.53804348 | C22: =C21+0.5% -> 0.11
B23: =(C23-$C$13)/$D$5 -> 0.59782609 | C23: =C22+0.5% -> 0.115
B24: =(C24-$C$13)/$D$5 -> 0.6576087 | C24: =C23+0.5% -> 0.12
B25: =(C25-$C$13)/$D$5 -> 0.7173913 | C25: =C24+0.5% -> 0.125
... B52: =(C52-$C$13)/$D$5 -> 2.3315217 | C52: =C51+0.5% -> 0.26

Sheet Flotation Cost
A1: proceed per share | B1: 250
A2: number of share | B2: 18000000000
A3: proceed | B3: =B1*B2 -> 4500000000000
A4: net proceed = proceed - out of pocket cost
A5: out of pocket cost
A6: - direct cost | B6: =1%*B3 -> 45000000000
A7: - indirect cost | B7: =0.25%*B3 -> 11250000000
A8: total out of pocket cost | B8: =B6+B7 -> 56250000000
A9: net proceed | B9: =B3-B8 -> 4443750000000
A12: direct cost:
A13: - out of pocket direct cost | B13: =B6 -> 45000000000
A14: - spread:
A15: proceed per share received by underwriter | B15: 289
A16: proceed per share received by issuer | B16: =B1 -> 250
A17: spread per share | B17: =B15-B16 -> 39
A18: number of share | B18: =B2 -> 18000000000
A19: spread = spread per share x number of share | B19: =B17*B18 -> 702000000000
A20: total direct cost | B20: =B13+B19 -> 747000000000
A23: indirect cost:
A24: - out of pocket indirect cost | B24: =B7 -> 11250000000
A25: - IPO underpricing
A26: traded price | B26: 300
A27: proceed per share received by underwriter | B27: =B15 -> 289
A28: underprice per share | B28: =B26-B27 -> 11
A29: number of share | B29: =B2 -> 18000000000
A30: underpricing = underprice per share x number of share | B30: =B28*B29 -> 198000000000
A31: total indirect cost | B31: =B24+B30 -> 209250000000
A33: flotation cost = total direct cost + total indirect cost
A34: floation cost | B34: =B20+B31 -> 956250000000
A35: floation cost as % of fund raised | B35: =B34/B9 -> 0.21518987
