Workbook

Sheet Example
B2: Speed Motor Inc. tengah mempertimbangkan untuk membangun fasilitas pabrik baru. Dana yang dibutuhkan untuk membeli (termasuk biaya pengiriman) mesin-mesin diperkirakan mencapai $ 10 juta. Harga beli diatas termasuk biaya pengiriman dan biaya instalasi mesin-mesin sampai dapat digunakan untuk operasional perusahaan. Namun biaya tersebut tidak termasuk biaya untuk melatih karyawan bagian produksi yang diperkirakan mencapai $200.000. Kebutuhan modal kerja diperkirakan sebesar $ 1 juta. Fasilitas pabrik akan dibangun diatas lahan perusahaan yang dibeli lima tahun lalu seharga $ 1 juta. Harga pasar lahan tersebut sekarang diperkirakan mencapai $ 2 juta, dan akan bernilai $ 3 juta pada lima tahun yang akan datang dan $ 4 juta sepuluh tahun yang akan datang. Mesin baru ini dapat digunakan sampai sepuluh tahun, namun perusahaan melihat bahwa setelah lima tahun, teknologi yang digunakan akan usang secara ekonomis. Setelah lima tahun perusahaan merencanakan akan mengganti mesin baru, dan pada akhir tahun kelima tersebut mesin diperkirakan masih dapat dijual seharga $ 3 juta. Operasionalisasi mesin baru diperkirakan akan menciptakan penjualan baru yang akan menghasilkan EBITDA (earning before interest, tax, depreciation and amortization) $ 4 juta / thn. Metode penyusutan yang digunakan adalah garis lurus tanpa nilai sisa. Tingkat pajak marjinal perusahaan adalah 22 %. Hitunglah: Hitunglah (1) IO, (2) Annual CF, (3) terminal CF, (4) IRR proyek

Sheet Scenario
B2: Base Case | C2: Worst Case | D2: Best Case
B3: EBITDA: 4.000.000 | C3: EBITDA: Turun menjadi 2.500.000 (permintaan pasar lesu). | D3: EBITDA: Naik menjadi 5.500.000.
B4: IO: 13.156.000 | C4: Initial Outlay: Membengkak menjadi 15.000.000 (biaya impor mesin naik karena kurs). | D4: Initial Outlay: Tetap atau lebih efisien di 12.500.000.
B5: Salvage Mesin: 3.000.000 | C5: Salvage Value: Harga mesin bekas jatuh ke 1.000.000 dan harga lahan stagnan di 2.000.000. | D5: Salvage Value: Harga lahan melonjak ke 4.500.000 di tahun ke-5.

Sheet IRR
B2: CAPEX | C2: 10000000 | D2: USD | F2: Nilai tanah
B3: Biaya pelatihan awal | C3: 200000 | D3: USD | F3: Y-5 | G3: 1000000 | H3: --- sunk cost
B4: Modal kerja | C4: 1000000 | D4: USD | F4: Y | G4: 2000000
B5: Masa manfaat | C5: 5 | D5: tahun | F5: Y+5 | G5: 3000000
B6: EBITDA/tahun | C6: 4000000 | D6: USD | F6: Y+10 | G6: 4000000
B7: Tarif pajak | C7: 0.22
B8: Discount rate | C8: 0.25
C11: 0 | D11: 1 | E11: 2 | F11: 3 | G11: 4 | H11: 5
B12: EBITDA | D12: =$C$6 -> 4000000 | E12: =$C$6 -> 4000000 | F12: =$C$6 -> 4000000 | G12: =$C$6 -> 4000000 | H12: =$C$6 -> 4000000
B13: Depresiasi | D13: =-$C$2/$C$5 -> -2000000 | E13: =-$C$2/$C$5 -> -2000000 | F13: =-$C$2/$C$5 -> -2000000 | G13: =-$C$2/$C$5 -> -2000000 | H13: =-$C$2/$C$5 -> -2000000
B14: EBIT | D14: =sum(D12:D13) -> 2000000 | E14: =sum(E12:E13) -> 2000000 | F14: =sum(F12:F13) -> 2000000 | G14: =sum(G12:G13) -> 2000000 | H14: =sum(H12:H13) -> 2000000
B15: Bunga | D15: 0 | E15: 0 | F15: 0 | G15: 0 | H15: 0
B16: EBT | D16: =sum(D14:D15) -> 2000000 | E16: =sum(E14:E15) -> 2000000 | F16: =sum(F14:F15) -> 2000000 | G16: =sum(G14:G15) -> 2000000 | H16: =sum(H14:H15) -> 2000000
B17: PPh | D17: =-$C$7*D16 -> -440000 | E17: =-$C$7*E16 -> -440000 | F17: =-$C$7*F16 -> -440000 | G17: =-$C$7*G16 -> -440000 | H17: =-$C$7*H16 -> -440000
B18: Laba neto | D18: =sum(D16:D17) -> 1560000 | E18: =sum(E16:E17) -> 1560000 | F18: =sum(F16:F17) -> 1560000 | G18: =sum(G16:G17) -> 1560000 | H18: =sum(H16:H17) -> 1560000
B19: Added back depresiasi | D19: =-D13 -> 2000000 | E19: =-E13 -> 2000000 | F19: =-F13 -> 2000000 | G19: =-G13 -> 2000000 | H19: =-H13 -> 2000000
B20: Operating cash flow | D20: =sum(D18:D19) -> 3560000 | E20: =sum(E18:E19) -> 3560000 | F20: =sum(F18:F19) -> 3560000 | G20: =sum(G18:G19) -> 3560000 | H20: =sum(H18:H19) -> 3560000
B21: Terminal cash flow | H21: =C57 -> 6340000
B22: Cash flow | C22: =C44 -> -13156000 | D22: =sum(D20:D21) -> 3560000 | E22: =sum(E20:E21) -> 3560000 | F22: =sum(F20:F21) -> 3560000 | G22: =sum(G20:G21) -> 3560000 | H22: =sum(H20:H21) -> 9900000
B23: IRR | C23: =irr(C22:H22) -> 0.20113302
B24: ="NPV at "&text(C8,"##,00%") -> NPV at 25% | C24: {=npv(C8,C22:H22)} -> -1203737.6
B27: Sensitivity Analysis on IRR | C27: 0.1
C28: EBITDA | D28: CAPEX | E28: Salvage
B29: -10% | C29: ='EBITDA -10'!C30 -> 0.17353651 | D29: ='Cost overrun -10'!C30 -> 0.23254058 | E29: ='Salvage value -10'!C30 -> 0.19756489
B30: Base | C30: =C23 -> 0.20113302 | D30: =C23 -> 0.20113302 | E30: =C23 -> 0.20113302
B31: +10% | C31: ='EBITDA +10'!C30 -> 0.22847604 | D31: ='Cost overrun +10'!C30 -> 0.17327685 | E31: ='Salvage value +10'!C30 -> 0.20464763
B33: Effect | C33: =C29-C30 -> -0.02759651 | D33: =D29-D30 -> 0.031407563 | E33: =E29-E30 -> -0.0035681323
B34: Effect | C34: =C31-C30 -> 0.027343021 | D34: =D31-D30 -> -0.027856164 | E34: =E31-E30 -> 0.0035146119
B37: Initial outlay:
A38: - | B38: Pembelian tanah | C38: 0
A39: - | B39: CAPEX | C39: =-C2 -> -10000000
A40: - | B40: Biaya pelatihan awal | C40: =-C3 -> -200000
A41: - | B41: Tax benefit atas biaya pelatihan | C41: =-C7*C40 -> 44000
A42: - | B42: Modal kerja | C42: =-C4 -> -1000000
A43: - | B43: Opportunity cost tanah | C43: =-G4 -> -2000000
B44: Total initial outlay | C44: =sum(C38:C43) -> -13156000
B47: Terminal cash flow:
B48: Harga beli mesin | C48: =C2 -> 10000000
B49: Akumulasi depresasi tahun ke-5 | C49: =-C2/C5*5 -> -10000000
B50: Nilai sisa | C50: =sum(C48:C49) -> 0
...

Sheet EBITDA -10
B2: Sensitivty variable:
B3: EBITDA | C3: =-IRR!C27 -> -0.1
B4: Initial outlay (cost overrun)
B5: Salvage value
B9: CAPEX | C9: 10000000 | D9: USD | F9: Nilai tanah
B10: Biaya pelatihan awal | C10: 200000 | D10: USD | F10: Y-5 | G10: 1000000 | H10: --- sunk cost
B11: Modal kerja | C11: 1000000 | D11: USD | F11: Y | G11: 2000000
B12: Masa manfaat | C12: 5 | D12: tahun | F12: Y+5 | G12: 3000000
B13: EBITDA/tahun | C13: 4000000 | D13: USD | F13: Y+10 | G13: 4000000
B14: Tarif pajak | C14: 0.22
B15: Discount rate | C15: 0.2
C18: 0 | D18: 1 | E18: 2 | F18: 3 | G18: 4 | H18: 5
B19: EBITDA | D19: =(1+$C$3)*$C$13 -> 3600000 | E19: =(1+$C$3)*$C$13 -> 3600000 | F19: =(1+$C$3)*$C$13 -> 3600000 | G19: =(1+$C$3)*$C$13 -> 3600000 | H19: =(1+$C$3)*$C$13 -> 3600000
B20: Depresiasi | D20: =-$C$9/$C$12 -> -2000000 | E20: =-$C$9/$C$12 -> -2000000 | F20: =-$C$9/$C$12 -> -2000000 | G20: =-$C$9/$C$12 -> -2000000 | H20: =-$C$9/$C$12 -> -2000000
B21: EBIT | D21: =sum(D19:D20) -> 1600000 | E21: =sum(E19:E20) -> 1600000 | F21: =sum(F19:F20) -> 1600000 | G21: =sum(G19:G20) -> 1600000 | H21: =sum(H19:H20) -> 1600000
B22: Bunga | D22: 0 | E22: 0 | F22: 0 | G22: 0 | H22: 0
B23: EBT | D23: =sum(D21:D22) -> 1600000 | E23: =sum(E21:E22) -> 1600000 | F23: =sum(F21:F22) -> 1600000 | G23: =sum(G21:G22) -> 1600000 | H23: =sum(H21:H22) -> 1600000
B24: PPh | D24: =-$C$14*D23 -> -352000 | E24: =-$C$14*E23 -> -352000 | F24: =-$C$14*F23 -> -352000 | G24: =-$C$14*G23 -> -352000 | H24: =-$C$14*H23 -> -352000
B25: Laba neto | D25: =sum(D23:D24) -> 1248000 | E25: =sum(E23:E24) -> 1248000 | F25: =sum(F23:F24) -> 1248000 | G25: =sum(G23:G24) -> 1248000 | H25: =sum(H23:H24) -> 1248000
B26: Added back depresiasi | D26: =-D20 -> 2000000 | E26: =-E20 -> 2000000 | F26: =-F20 -> 2000000 | G26: =-G20 -> 2000000 | H26: =-H20 -> 2000000
B27: Operating cash flow | D27: =sum(D25:D26) -> 3248000 | E27: =sum(E25:E26) -> 3248000 | F27: =sum(F25:F26) -> 3248000 | G27: =sum(G25:G26) -> 3248000 | H27: =sum(H25:H26) -> 3248000
B28: Terminal cash flow | H28: =C54 -> 6340000
B29: Cash flow | C29: =C41 -> -13156000 | D29: =sum(D27:D28) -> 3248000 | E29: =sum(E27:E28) -> 3248000 | F29: =sum(F27:F28) -> 3248000 | G29: =sum(G27:G28) -> 3248000 | H29: =sum(H27:H28) -> 9588000
B30: IRR | C30: =irr(C29:H29) -> 0.17353651
B31: ="NPV at "&text(C15,"##,00%") -> NPV at 20% | C31: {=npv(C15,C29:H29)} -> -745489.97
B34: Initial outlay:
A35: - | B35: Pembelian tanah | C35: 0
A36: - | B36: CAPEX | C36: =-C9 -> -10000000
A37: - | B37: Biaya pelatihan awal | C37: =-C10 -> -200000
A38: - | B38: Tax benefit atas biaya pelatihan | C38: =-C14*C37 -> 44000
A39: - | B39: Modal kerja | C39: =-C11 -> -1000000
A40: - | B40: Opportunity cost tanah | C40: =-G11 -> -2000000
B41: Total initial outlay | C41: =sum(C35:C40) -> -13156000
B44: Terminal cash flow:
B45: Harga beli mesin | C45: =C9 -> 10000000
B46: Akumulasi depresasi tahun ke-5 | C46: =-C9/C12*5 -> -10000000
B47: Nilai sisa | C47: =sum(C45:C46) -> 0
B48: Harga jual mesin | C48: 3000000
B49: Keuntungan dari penjualan bruto | C49: =C48-C47 -> 3000000
B50: Pajak atas keuntungan dari penjualan mesin | C50: =-C14*C49 -> -660000
...

Sheet Salvage value -10
B2: Sensitivty variable:
B3: EBITDA
B4: Initial outlay (cost overrun)
B5: Salvage value | C5: =-IRR!C27 -> -0.1
B9: CAPEX | C9: 10000000 | D9: USD | F9: Nilai tanah
B10: Biaya pelatihan awal | C10: 200000 | D10: USD | F10: Y-5 | G10: 1000000 | H10: --- sunk cost
B11: Modal kerja | C11: 1000000 | D11: USD | F11: Y | G11: 2000000
B12: Masa manfaat | C12: 5 | D12: tahun | F12: Y+5 | G12: =3000000*(1+C5) -> 2700000
B13: EBITDA/tahun | C13: 4000000 | D13: USD | F13: Y+10 | G13: 4000000
B14: Tarif pajak | C14: 0.22
B15: Discount rate | C15: 0.2
C18: 0 | D18: 1 | E18: 2 | F18: 3 | G18: 4 | H18: 5
B19: EBITDA | D19: =(1+$C$3)*$C$13 -> 4000000 | E19: =(1+$C$3)*$C$13 -> 4000000 | F19: =(1+$C$3)*$C$13 -> 4000000 | G19: =(1+$C$3)*$C$13 -> 4000000 | H19: =(1+$C$3)*$C$13 -> 4000000
B20: Depresiasi | D20: =-$C$9/$C$12 -> -2000000 | E20: =-$C$9/$C$12 -> -2000000 | F20: =-$C$9/$C$12 -> -2000000 | G20: =-$C$9/$C$12 -> -2000000 | H20: =-$C$9/$C$12 -> -2000000
B21: EBIT | D21: =sum(D19:D20) -> 2000000 | E21: =sum(E19:E20) -> 2000000 | F21: =sum(F19:F20) -> 2000000 | G21: =sum(G19:G20) -> 2000000 | H21: =sum(H19:H20) -> 2000000
B22: Bunga | D22: 0 | E22: 0 | F22: 0 | G22: 0 | H22: 0
B23: EBT | D23: =sum(D21:D22) -> 2000000 | E23: =sum(E21:E22) -> 2000000 | F23: =sum(F21:F22) -> 2000000 | G23: =sum(G21:G22) -> 2000000 | H23: =sum(H21:H22) -> 2000000
B24: PPh | D24: =-$C$14*D23 -> -440000 | E24: =-$C$14*E23 -> -440000 | F24: =-$C$14*F23 -> -440000 | G24: =-$C$14*G23 -> -440000 | H24: =-$C$14*H23 -> -440000
B25: Laba neto | D25: =sum(D23:D24) -> 1560000 | E25: =sum(E23:E24) -> 1560000 | F25: =sum(F23:F24) -> 1560000 | G25: =sum(G23:G24) -> 1560000 | H25: =sum(H23:H24) -> 1560000
B26: Added back depresiasi | D26: =-D20 -> 2000000 | E26: =-E20 -> 2000000 | F26: =-F20 -> 2000000 | G26: =-G20 -> 2000000 | H26: =-H20 -> 2000000
B27: Operating cash flow | D27: =sum(D25:D26) -> 3560000 | E27: =sum(E25:E26) -> 3560000 | F27: =sum(F25:F26) -> 3560000 | G27: =sum(G25:G26) -> 3560000 | H27: =sum(H25:H26) -> 3560000
B28: Terminal cash flow | H28: =C54 -> 6040000
B29: Cash flow | C29: =C41 -> -13156000 | D29: =sum(D27:D28) -> 3560000 | E29: =sum(E27:E28) -> 3560000 | F29: =sum(F27:F28) -> 3560000 | G29: =sum(G27:G28) -> 3560000 | H29: =sum(H27:H28) -> 9600000
B30: IRR | C30: =irr(C29:H29) -> 0.19756489
B31: ="NPV at "&text(C15,"##,00%") -> NPV at 20% | C31: {=npv(C15,C29:H29)} -> -68400.206
B34: Initial outlay:
A35: - | B35: Pembelian tanah | C35: 0
A36: - | B36: CAPEX | C36: =-C9 -> -10000000
A37: - | B37: Biaya pelatihan awal | C37: =-C10 -> -200000
A38: - | B38: Tax benefit atas biaya pelatihan | C38: =-C14*C37 -> 44000
A39: - | B39: Modal kerja | C39: =-C11 -> -1000000
A40: - | B40: Opportunity cost tanah | C40: =-G11 -> -2000000
B41: Total initial outlay | C41: =sum(C35:C40) -> -13156000
B44: Terminal cash flow:
B45: Harga beli mesin | C45: =C9 -> 10000000
B46: Akumulasi depresasi tahun ke-5 | C46: =-C9/C12*5 -> -10000000
B47: Nilai sisa | C47: =sum(C45:C46) -> 0
B48: Harga jual mesin | C48: 3000000
B49: Keuntungan dari penjualan bruto | C49: =C48-C47 -> 3000000
B50: Pajak atas keuntungan dari penjualan mesin | C50: =-C14*C49 -> -660000
...

Sheet Salvage value +10
B2: Sensitivty variable:
B3: EBITDA
B4: Initial outlay (cost overrun)
B5: Salvage value | C5: 0.1
B9: CAPEX | C9: 10000000 | D9: USD | F9: Nilai tanah
B10: Biaya pelatihan awal | C10: 200000 | D10: USD | F10: Y-5 | G10: 1000000 | H10: --- sunk cost
B11: Modal kerja | C11: 1000000 | D11: USD | F11: Y | G11: 2000000
B12: Masa manfaat | C12: 5 | D12: tahun | F12: Y+5 | G12: =3000000*(1+C5) -> 3300000
B13: EBITDA/tahun | C13: 4000000 | D13: USD | F13: Y+10 | G13: 4000000
B14: Tarif pajak | C14: 0.22
B15: Discount rate | C15: 0.2
C18: 0 | D18: 1 | E18: 2 | F18: 3 | G18: 4 | H18: 5
B19: EBITDA | D19: =(1+$C$3)*$C$13 -> 4000000 | E19: =(1+$C$3)*$C$13 -> 4000000 | F19: =(1+$C$3)*$C$13 -> 4000000 | G19: =(1+$C$3)*$C$13 -> 4000000 | H19: =(1+$C$3)*$C$13 -> 4000000
B20: Depresiasi | D20: =-$C$9/$C$12 -> -2000000 | E20: =-$C$9/$C$12 -> -2000000 | F20: =-$C$9/$C$12 -> -2000000 | G20: =-$C$9/$C$12 -> -2000000 | H20: =-$C$9/$C$12 -> -2000000
B21: EBIT | D21: =sum(D19:D20) -> 2000000 | E21: =sum(E19:E20) -> 2000000 | F21: =sum(F19:F20) -> 2000000 | G21: =sum(G19:G20) -> 2000000 | H21: =sum(H19:H20) -> 2000000
B22: Bunga | D22: 0 | E22: 0 | F22: 0 | G22: 0 | H22: 0
B23: EBT | D23: =sum(D21:D22) -> 2000000 | E23: =sum(E21:E22) -> 2000000 | F23: =sum(F21:F22) -> 2000000 | G23: =sum(G21:G22) -> 2000000 | H23: =sum(H21:H22) -> 2000000
B24: PPh | D24: =-$C$14*D23 -> -440000 | E24: =-$C$14*E23 -> -440000 | F24: =-$C$14*F23 -> -440000 | G24: =-$C$14*G23 -> -440000 | H24: =-$C$14*H23 -> -440000
B25: Laba neto | D25: =sum(D23:D24) -> 1560000 | E25: =sum(E23:E24) -> 1560000 | F25: =sum(F23:F24) -> 1560000 | G25: =sum(G23:G24) -> 1560000 | H25: =sum(H23:H24) -> 1560000
B26: Added back depresiasi | D26: =-D20 -> 2000000 | E26: =-E20 -> 2000000 | F26: =-F20 -> 2000000 | G26: =-G20 -> 2000000 | H26: =-H20 -> 2000000
B27: Operating cash flow | D27: =sum(D25:D26) -> 3560000 | E27: =sum(E25:E26) -> 3560000 | F27: =sum(F25:F26) -> 3560000 | G27: =sum(G25:G26) -> 3560000 | H27: =sum(H25:H26) -> 3560000
B28: Terminal cash flow | H28: =C54 -> 6640000
B29: Cash flow | C29: =C41 -> -13156000 | D29: =sum(D27:D28) -> 3560000 | E29: =sum(E27:E28) -> 3560000 | F29: =sum(F27:F28) -> 3560000 | G29: =sum(G27:G28) -> 3560000 | H29: =sum(H27:H28) -> 10200000
B30: IRR | C30: =irr(C29:H29) -> 0.20464763
B31: ="NPV at "&text(C15,"##,00%") -> NPV at 20% | C31: {=npv(C15,C29:H29)} -> 132538.58
B34: Initial outlay:
A35: - | B35: Pembelian tanah | C35: 0
A36: - | B36: CAPEX | C36: =-C9 -> -10000000
A37: - | B37: Biaya pelatihan awal | C37: =-C10 -> -200000
A38: - | B38: Tax benefit atas biaya pelatihan | C38: =-C14*C37 -> 44000
A39: - | B39: Modal kerja | C39: =-C11 -> -1000000
A40: - | B40: Opportunity cost tanah | C40: =-G11 -> -2000000
B41: Total initial outlay | C41: =sum(C35:C40) -> -13156000
B44: Terminal cash flow:
B45: Harga beli mesin | C45: =C9 -> 10000000
B46: Akumulasi depresasi tahun ke-5 | C46: =-C9/C12*5 -> -10000000
B47: Nilai sisa | C47: =sum(C45:C46) -> 0
B48: Harga jual mesin | C48: 3000000
B49: Keuntungan dari penjualan bruto | C49: =C48-C47 -> 3000000
B50: Pajak atas keuntungan dari penjualan mesin | C50: =-C14*C49 -> -660000
...

Sheet EBITDA +10
B2: Sensitivty variable:
B3: EBITDA | C3: =IRR!C27 -> 0.1
B4: Initial outlay (cost overrun)
B5: Salvage value
B9: CAPEX | C9: 10000000 | D9: USD | F9: Nilai tanah
B10: Biaya pelatihan awal | C10: 200000 | D10: USD | F10: Y-5 | G10: 1000000 | H10: --- sunk cost
B11: Modal kerja | C11: 1000000 | D11: USD | F11: Y | G11: 2000000
B12: Masa manfaat | C12: 5 | D12: tahun | F12: Y+5 | G12: 3000000
B13: EBITDA/tahun | C13: 4000000 | D13: USD | F13: Y+10 | G13: 4000000
B14: Tarif pajak | C14: 0.22
B15: Discount rate | C15: 0.2
C18: 0 | D18: 1 | E18: 2 | F18: 3 | G18: 4 | H18: 5
B19: EBITDA | D19: =(1+$C$3)*$C$13 -> 4400000 | E19: =(1+$C$3)*$C$13 -> 4400000 | F19: =(1+$C$3)*$C$13 -> 4400000 | G19: =(1+$C$3)*$C$13 -> 4400000 | H19: =(1+$C$3)*$C$13 -> 4400000
B20: Depresiasi | D20: =-$C$9/$C$12 -> -2000000 | E20: =-$C$9/$C$12 -> -2000000 | F20: =-$C$9/$C$12 -> -2000000 | G20: =-$C$9/$C$12 -> -2000000 | H20: =-$C$9/$C$12 -> -2000000
B21: EBIT | D21: =sum(D19:D20) -> 2400000 | E21: =sum(E19:E20) -> 2400000 | F21: =sum(F19:F20) -> 2400000 | G21: =sum(G19:G20) -> 2400000 | H21: =sum(H19:H20) -> 2400000
B22: Bunga | D22: 0 | E22: 0 | F22: 0 | G22: 0 | H22: 0
B23: EBT | D23: =sum(D21:D22) -> 2400000 | E23: =sum(E21:E22) -> 2400000 | F23: =sum(F21:F22) -> 2400000 | G23: =sum(G21:G22) -> 2400000 | H23: =sum(H21:H22) -> 2400000
B24: PPh | D24: =-$C$14*D23 -> -528000 | E24: =-$C$14*E23 -> -528000 | F24: =-$C$14*F23 -> -528000 | G24: =-$C$14*G23 -> -528000 | H24: =-$C$14*H23 -> -528000
B25: Laba neto | D25: =sum(D23:D24) -> 1872000 | E25: =sum(E23:E24) -> 1872000 | F25: =sum(F23:F24) -> 1872000 | G25: =sum(G23:G24) -> 1872000 | H25: =sum(H23:H24) -> 1872000
B26: Added back depresiasi | D26: =-D20 -> 2000000 | E26: =-E20 -> 2000000 | F26: =-F20 -> 2000000 | G26: =-G20 -> 2000000 | H26: =-H20 -> 2000000
B27: Operating cash flow | D27: =sum(D25:D26) -> 3872000 | E27: =sum(E25:E26) -> 3872000 | F27: =sum(F25:F26) -> 3872000 | G27: =sum(G25:G26) -> 3872000 | H27: =sum(H25:H26) -> 3872000
B28: Terminal cash flow | H28: =C54 -> 6340000
B29: Cash flow | C29: =C41 -> -13156000 | D29: =sum(D27:D28) -> 3872000 | E29: =sum(E27:E28) -> 3872000 | F29: =sum(F27:F28) -> 3872000 | G29: =sum(G27:G28) -> 3872000 | H29: =sum(H27:H28) -> 10212000
B30: IRR | C30: =irr(C29:H29) -> 0.22847604
B31: ="NPV at "&text(C15,"##,00%") -> NPV at 20% | C31: {=npv(C15,C29:H29)} -> 809628.34
B34: Initial outlay:
A35: - | B35: Pembelian tanah | C35: 0
A36: - | B36: CAPEX | C36: =-C9 -> -10000000
A37: - | B37: Biaya pelatihan awal | C37: =-C10 -> -200000
A38: - | B38: Tax benefit atas biaya pelatihan | C38: =-C14*C37 -> 44000
A39: - | B39: Modal kerja | C39: =-C11 -> -1000000
A40: - | B40: Opportunity cost tanah | C40: =-G11 -> -2000000
B41: Total initial outlay | C41: =sum(C35:C40) -> -13156000
B44: Terminal cash flow:
B45: Harga beli mesin | C45: =C9 -> 10000000
B46: Akumulasi depresasi tahun ke-5 | C46: =-C9/C12*5 -> -10000000
B47: Nilai sisa | C47: =sum(C45:C46) -> 0
B48: Harga jual mesin | C48: 3000000
B49: Keuntungan dari penjualan bruto | C49: =C48-C47 -> 3000000
B50: Pajak atas keuntungan dari penjualan mesin | C50: =-C14*C49 -> -660000
...

Sheet Cost overrun -10
B2: Sensitivty variable:
B3: EBITDA
B4: Initial outlay (cost overrun) | C4: =-IRR!C27 -> -0.1
B5: Salvage value
B9: CAPEX | C9: 10000000 | D9: USD | F9: Nilai tanah
B10: Biaya pelatihan awal | C10: 200000 | D10: USD | F10: Y-5 | G10: 1000000 | H10: --- sunk cost
B11: Modal kerja | C11: 1000000 | D11: USD | F11: Y | G11: 2000000
B12: Masa manfaat | C12: 5 | D12: tahun | F12: Y+5 | G12: 3000000
B13: EBITDA/tahun | C13: 4000000 | D13: USD | F13: Y+10 | G13: 4000000
B14: Tarif pajak | C14: 0.22
B15: Discount rate | C15: 0.2
C18: 0 | D18: 1 | E18: 2 | F18: 3 | G18: 4 | H18: 5
B19: EBITDA | D19: =(1+$C$3)*$C$13 -> 4000000 | E19: =(1+$C$3)*$C$13 -> 4000000 | F19: =(1+$C$3)*$C$13 -> 4000000 | G19: =(1+$C$3)*$C$13 -> 4000000 | H19: =(1+$C$3)*$C$13 -> 4000000
B20: Depresiasi | D20: =-$C$9/$C$12 -> -2000000 | E20: =-$C$9/$C$12 -> -2000000 | F20: =-$C$9/$C$12 -> -2000000 | G20: =-$C$9/$C$12 -> -2000000 | H20: =-$C$9/$C$12 -> -2000000
B21: EBIT | D21: =sum(D19:D20) -> 2000000 | E21: =sum(E19:E20) -> 2000000 | F21: =sum(F19:F20) -> 2000000 | G21: =sum(G19:G20) -> 2000000 | H21: =sum(H19:H20) -> 2000000
B22: Bunga | D22: 0 | E22: 0 | F22: 0 | G22: 0 | H22: 0
B23: EBT | D23: =sum(D21:D22) -> 2000000 | E23: =sum(E21:E22) -> 2000000 | F23: =sum(F21:F22) -> 2000000 | G23: =sum(G21:G22) -> 2000000 | H23: =sum(H21:H22) -> 2000000
B24: PPh | D24: =-$C$14*D23 -> -440000 | E24: =-$C$14*E23 -> -440000 | F24: =-$C$14*F23 -> -440000 | G24: =-$C$14*G23 -> -440000 | H24: =-$C$14*H23 -> -440000
B25: Laba neto | D25: =sum(D23:D24) -> 1560000 | E25: =sum(E23:E24) -> 1560000 | F25: =sum(F23:F24) -> 1560000 | G25: =sum(G23:G24) -> 1560000 | H25: =sum(H23:H24) -> 1560000
B26: Added back depresiasi | D26: =-D20 -> 2000000 | E26: =-E20 -> 2000000 | F26: =-F20 -> 2000000 | G26: =-G20 -> 2000000 | H26: =-H20 -> 2000000
B27: Operating cash flow | D27: =sum(D25:D26) -> 3560000 | E27: =sum(E25:E26) -> 3560000 | F27: =sum(F25:F26) -> 3560000 | G27: =sum(G25:G26) -> 3560000 | H27: =sum(H25:H26) -> 3560000
B28: Terminal cash flow | H28: =C54 -> 6340000
B29: Cash flow | C29: =C41 -> -12156000 | D29: =sum(D27:D28) -> 3560000 | E29: =sum(E27:E28) -> 3560000 | F29: =sum(F27:F28) -> 3560000 | G29: =sum(G27:G28) -> 3560000 | H29: =sum(H27:H28) -> 9900000
B30: IRR | C30: =irr(C29:H29) -> 0.23254058
B31: ="NPV at "&text(C15,"##,00%") -> NPV at 20% | C31: {=npv(C15,C29:H29)} -> 865402.52
B34: Initial outlay:
A35: - | B35: Pembelian tanah | C35: 0
A36: - | B36: CAPEX | C36: =-(C9*(1+C4)) -> -9000000
A37: - | B37: Biaya pelatihan awal | C37: =-C10 -> -200000
A38: - | B38: Tax benefit atas biaya pelatihan | C38: =-C14*C37 -> 44000
A39: - | B39: Modal kerja | C39: =-C11 -> -1000000
A40: - | B40: Opportunity cost tanah | C40: =-G11 -> -2000000
B41: Total initial outlay | C41: =sum(C35:C40) -> -12156000
B44: Terminal cash flow:
B45: Harga beli mesin | C45: =C9 -> 10000000
B46: Akumulasi depresasi tahun ke-5 | C46: =-C9/C12*5 -> -10000000
B47: Nilai sisa | C47: =sum(C45:C46) -> 0
B48: Harga jual mesin | C48: 3000000
B49: Keuntungan dari penjualan bruto | C49: =C48-C47 -> 3000000
B50: Pajak atas keuntungan dari penjualan mesin | C50: =-C14*C49 -> -660000
...

Sheet Cost overrun +10
B2: Sensitivty variable:
B3: EBITDA
B4: Initial outlay (cost overrun) | C4: =IRR!C27 -> 0.1
B5: Salvage value
B9: CAPEX | C9: 10000000 | D9: USD | F9: Nilai tanah
B10: Biaya pelatihan awal | C10: 200000 | D10: USD | F10: Y-5 | G10: 1000000 | H10: --- sunk cost
B11: Modal kerja | C11: 1000000 | D11: USD | F11: Y | G11: 2000000
B12: Masa manfaat | C12: 5 | D12: tahun | F12: Y+5 | G12: 3000000
B13: EBITDA/tahun | C13: 4000000 | D13: USD | F13: Y+10 | G13: 4000000
B14: Tarif pajak | C14: 0.22
B15: Discount rate | C15: 0.2
C18: 0 | D18: 1 | E18: 2 | F18: 3 | G18: 4 | H18: 5
B19: EBITDA | D19: =(1+$C$3)*$C$13 -> 4000000 | E19: =(1+$C$3)*$C$13 -> 4000000 | F19: =(1+$C$3)*$C$13 -> 4000000 | G19: =(1+$C$3)*$C$13 -> 4000000 | H19: =(1+$C$3)*$C$13 -> 4000000
B20: Depresiasi | D20: =-$C$9/$C$12 -> -2000000 | E20: =-$C$9/$C$12 -> -2000000 | F20: =-$C$9/$C$12 -> -2000000 | G20: =-$C$9/$C$12 -> -2000000 | H20: =-$C$9/$C$12 -> -2000000
B21: EBIT | D21: =sum(D19:D20) -> 2000000 | E21: =sum(E19:E20) -> 2000000 | F21: =sum(F19:F20) -> 2000000 | G21: =sum(G19:G20) -> 2000000 | H21: =sum(H19:H20) -> 2000000
B22: Bunga | D22: 0 | E22: 0 | F22: 0 | G22: 0 | H22: 0
B23: EBT | D23: =sum(D21:D22) -> 2000000 | E23: =sum(E21:E22) -> 2000000 | F23: =sum(F21:F22) -> 2000000 | G23: =sum(G21:G22) -> 2000000 | H23: =sum(H21:H22) -> 2000000
B24: PPh | D24: =-$C$14*D23 -> -440000 | E24: =-$C$14*E23 -> -440000 | F24: =-$C$14*F23 -> -440000 | G24: =-$C$14*G23 -> -440000 | H24: =-$C$14*H23 -> -440000
B25: Laba neto | D25: =sum(D23:D24) -> 1560000 | E25: =sum(E23:E24) -> 1560000 | F25: =sum(F23:F24) -> 1560000 | G25: =sum(G23:G24) -> 1560000 | H25: =sum(H23:H24) -> 1560000
B26: Added back depresiasi | D26: =-D20 -> 2000000 | E26: =-E20 -> 2000000 | F26: =-F20 -> 2000000 | G26: =-G20 -> 2000000 | H26: =-H20 -> 2000000
B27: Operating cash flow | D27: =sum(D25:D26) -> 3560000 | E27: =sum(E25:E26) -> 3560000 | F27: =sum(F25:F26) -> 3560000 | G27: =sum(G25:G26) -> 3560000 | H27: =sum(H25:H26) -> 3560000
B28: Terminal cash flow | H28: =C54 -> 6340000
B29: Cash flow | C29: =C41 -> -14156000 | D29: =sum(D27:D28) -> 3560000 | E29: =sum(E27:E28) -> 3560000 | F29: =sum(F27:F28) -> 3560000 | G29: =sum(G27:G28) -> 3560000 | H29: =sum(H27:H28) -> 9900000
B30: IRR | C30: =irr(C29:H29) -> 0.17327685
B31: ="NPV at "&text(C15,"##,00%") -> NPV at 20% | C31: {=npv(C15,C29:H29)} -> -801264.15
B34: Initial outlay:
A35: - | B35: Pembelian tanah | C35: 0
A36: - | B36: CAPEX | C36: =-(C9*(1+C4)) -> -11000000
A37: - | B37: Biaya pelatihan awal | C37: =-C10 -> -200000
A38: - | B38: Tax benefit atas biaya pelatihan | C38: =-C14*C37 -> 44000
A39: - | B39: Modal kerja | C39: =-C11 -> -1000000
A40: - | B40: Opportunity cost tanah | C40: =-G11 -> -2000000
B41: Total initial outlay | C41: =sum(C35:C40) -> -14156000
B44: Terminal cash flow:
B45: Harga beli mesin | C45: =C9 -> 10000000
B46: Akumulasi depresasi tahun ke-5 | C46: =-C9/C12*5 -> -10000000
B47: Nilai sisa | C47: =sum(C45:C46) -> 0
B48: Harga jual mesin | C48: 3000000
B49: Keuntungan dari penjualan bruto | C49: =C48-C47 -> 3000000
B50: Pajak atas keuntungan dari penjualan mesin | C50: =-C14*C49 -> -660000
...
